<?xml version="1.0" encoding="utf-8"?>
<robot name="mobile_manipulator" xmlns:xacro="http://wiki.ros.org/xacro">
  <material name="dark_grey">
    <color rgba="0.2 0.2 0.2 1.0"/>
  </material>
  <material name="light_grey">
    <color rgba="0.4 0.4 0.4 1.0"/>
  </material>
  <material name="red">
    <color rgba="0.8 0.0 0.0 1.0"/>
  </material>
  <material name="white">
    <color rgba="0.9 0.9 0.9 1.0"/>
  </material>
  <material name="yellow">
    <color rgba="0.8 0.8 0.0 1.0"/>
  </material>
  <material name="black">
    <color rgba="0.15 0.15 0.15 1.0"/>
  </material>
  <material name="seethrough">
    <color rgba="1.0 0.0 0.0 0.25"/>
  </material>

  <xacro:arg name="kinematics_params" default="$(find mmmwe)/assets/params/kinematics_parameters.yaml"/>
  <xacro:arg name="visual_params" default="$(find mmmwe)/assets/params/visual_parameters.yaml"/>

  <link name="world_link">
    <inertial>
      <mass value="0"/>
      <inertia ixx="0.2125" ixy="-0.005" ixz="0.0225" iyy="0.205" iyz="0.045" izz="0.0125"/>
      <origin rpy="0 0 0" xyz="0 0 0"/>
    </inertial>
  </link>

	<link name="x_prismatic_link">
	 <inertial>
     <mass value="0.01"/>
     <inertia ixx="0.01" ixy="0" ixz="0" iyy="0.01" iyz="0" izz="0.01"/>
     <origin rpy="0 0 0" xyz="0 0 0"/>
    </inertial>
  </link>

	<joint name="x_to_world_joint" type="prismatic">
    <parent link="world_link"/>
    <child link="x_prismatic_link"/>
    <axis xyz="1 0 0"/>
    <origin rpy="0 0 0" xyz="0 0 0"/>
    <limit effort="0.0" velocity="1000.0"/>
  </joint>

	<link name="y_prismatic_link">
	 <inertial>
     <mass value="0.01"/>
     <inertia ixx="0.01" ixy="0" ixz="0" iyy="0.01" iyz="0" izz="0.01"/>
     <origin rpy="0 0 0" xyz="0 0 0"/>
    </inertial>
  </link>

	<joint name="y_to_x_joint" type="prismatic">
    <parent link="x_prismatic_link"/>
    <child link="y_prismatic_link"/>
    <axis xyz="0 1 0"/>
    <origin rpy="0 0 0" xyz="0 0 0"/>
    <limit effort="0.0" velocity="1000.0"/>
  </joint>

	<joint name="base_to_y_joint" type="continuous">
    <parent link="y_prismatic_link"/>
    <child link="base_link"/>
    <axis xyz="0 0 1"/>
    <origin rpy="0 0 0" xyz="0 0 0"/>
  </joint>

  <link name="base_link">
	 <inertial>
     <mass value="0.01"/>
     <inertia ixx="0.01" ixy="0" ixz="0" iyy="0.01" iyz="0" izz="0.01"/>
     <origin rpy="0 0 0" xyz="0 0 0"/>
    </inertial>
  </link>

  <!-- Note the z-offset to raise the base off the ground, to avoid collision issues in simulation. Without this, there are vibrations and other artifacts from resolving the ground collision that result in significant error in the balanced object. We include it in general for the real robot as well for consistency, to be resolved by calibration. -->
  <joint name="dummy_base_link_joint" type="fixed">
    <origin rpy="0 0 0" xyz="0 0 0.01"/>
    <parent link="base_link"/>
    <child link="dummy_base_link"/>
  </joint>
  <link name="dummy_base_link"/>

  <!-- Transform between base and arm can be calibrated and is loaded from parameters. -->
  <joint name="base_link_joint" type="fixed">
    <origin rpy="0 0 0" xyz="0 0 0"/>
    <parent link="dummy_base_link"/>
    <child link="chassis_link"/>
  </joint>

  <link name="chassis_link">
    <visual>
      <geometry>
        <mesh filename="file://$(find mmmwe)/assets/meshes/ridgeback/body.stl"/>
      </geometry>
      <material name="black"/>
    </visual>
    <collision>
      <origin xyz="0 0 0"/>
      <geometry>
        <mesh filename="file://$(find mmmwe)/assets/meshes/ridgeback/body-collision.stl"/>
      </geometry>
    </collision>
    <inertial>
      <origin rpy="1.57079632679 0 1.57079632679" xyz="0.012 0.002 0.067"/>
      <!-- <origin rpy="1.57079632679 0 1.57079632679" xyz="0 0 0"/> -->
      <mass value="165.304"/>
      <inertia ixx="4.4744" ixy="0.03098" ixz="0.003647" iyy="7.1624" iyz="0.1228" izz="4.6155"/>
    </inertial>
  </link>
  <joint name="right_side_cover_link_joint" type="fixed">
    <origin rpy="0 0 0" xyz="0 0 0"/>
    <parent link="chassis_link"/>
    <child link="right_side_cover_link"/>
  </joint>
  <joint name="left_side_cover_link_joint" type="fixed">
    <origin rpy="0 0 0" xyz="0 0 0"/>
    <parent link="chassis_link"/>
    <child link="left_side_cover_link"/>
  </joint>
  <link name="left_side_cover_link">
    <visual>
      <origin rpy="0 0 3.14159265359" xyz="0 0 0"/>
      <geometry>
        <mesh filename="file://$(find mmmwe)/assets/meshes/ridgeback/side-cover.stl"/>
      </geometry>
      <material name="yellow"/>
    </visual>
  </link>
  <link name="right_side_cover_link">
    <visual>
      <origin rpy="0 0 0" xyz="0 0 0"/>
      <geometry>
        <mesh filename="file://$(find mmmwe)/assets/meshes/ridgeback/side-cover.stl"/>
      </geometry>
      <material name="yellow"/>
    </visual>
  </link>
  <joint name="front_cover_link_joint" type="fixed">
    <origin rpy="0 0 0" xyz="0 0 0"/>
    <parent link="chassis_link"/>
    <child link="front_cover_link"/>
  </joint>
  <link name="front_cover_link">
    <visual>
      <origin rpy="0 0 0" xyz="0 0 0"/>
      <geometry>
        <mesh filename="file://$(find mmmwe)/assets/meshes/ridgeback/end-cover.stl"/>
      </geometry>
      <material name="black"/>
    </visual>
  </link>
  <joint name="rear_cover_link_joint" type="fixed">
    <origin rpy="0 0 0" xyz="0 0 0"/>
    <parent link="chassis_link"/>
    <child link="rear_cover_link"/>
  </joint>
  <link name="rear_cover_link">
    <visual>
      <origin rpy="0 0 3.14159265359" xyz="0 0 0"/>
      <geometry>
        <mesh filename="file://$(find mmmwe)/assets/meshes/ridgeback/end-cover.stl"/>
      </geometry>
      <material name="black"/>
    </visual>
  </link>
  <joint name="front_lights_link_joint" type="fixed">
    <origin rpy="0 0 0" xyz="0 0 0"/>
    <parent link="chassis_link"/>
    <child link="front_lights_link"/>
  </joint>
  <joint name="rear_lights_link_joint" type="fixed">
    <origin rpy="0 0 0" xyz="0 0 0"/>
    <parent link="chassis_link"/>
    <child link="rear_lights_link"/>
  </joint>
  <link name="front_lights_link">
    <visual>
      <origin rpy="0 0 0" xyz="0 0 0"/>
      <geometry>
        <mesh filename="file://$(find mmmwe)/assets/meshes/ridgeback/lights.stl"/>
      </geometry>
      <material name="white"/>
    </visual>
  </link>
  <link name="rear_lights_link">
    <visual>
      <origin rpy="0 0 3.14159265359" xyz="0 0 0"/>
      <geometry>
        <mesh filename="file://$(find mmmwe)/assets/meshes/ridgeback/lights.stl"/>
      </geometry>
      <material name="red"/>
    </visual>
  </link>
  <joint name="top_link_joint" type="fixed">
    <origin rpy="0 0 0" xyz="0 0 0"/>
    <parent link="chassis_link"/>
    <child link="top_link"/>
  </joint>
  <link name="top_link">
    <visual>
      <origin rpy="0 0 0" xyz="0 0 0"/>
      <geometry>
        <mesh filename="file://$(find mmmwe)/assets/meshes/ridgeback/top.stl"/>
      </geometry>
      <material name="black"/>
    </visual>
    <collision>
      <origin rpy="0 0 0" xyz="0 0 0"/>
      <geometry>
        <mesh filename="file://$(find mmmwe)/assets/meshes/ridgeback/top.stl"/>
      </geometry>
    </collision>
  </link>

  <link name="arch_link">
    <visual>
      <geometry>
        <mesh filename="file://$(find mmmwe)/assets/meshes/tor11_mech.dae"/>
      </geometry>
      <material name="LightGrey">
        <color rgba="0.7 0.7 0.7 1.0"/>
      </material>
    </visual>
  </link>
  <joint name="arch_joint" type="fixed">
    <origin rpy="0 0 1.57079632679" xyz="0 0 0.278"/>
    <!-- <origin rpy="-1.57079632679 0 1.57079632679" xyz="0 0 0.278"/> -->
    <parent link="top_link"/>
    <child link="arch_link"/>
  </joint>

  <!-- UR10 arm -->
  <xacro:include filename="$(find ur_description)/urdf/inc/ur10_macro.xacro"/>
  <xacro:ur10_robot
    prefix="ur10_arm_"
    visual_parameters_file="$(arg visual_params)"
    kinematics_parameters_file="$(arg kinematics_params)"
  />

  <!-- Join arm to the base -->
  <joint name="ur10_arm_base_joint" type="fixed">
    <parent link="arch_link"/>
    <child link="ur10_arm_base_link"/>
    <origin rpy="0.0 0.0 3.14159265359" xyz="0.01 -0.27 0.375"/>
  </joint>

  <!-- Frame coincident with all-zeros TCP on UR controller -->
  <link name="gripper">
    <visual>
      <!-- start halfway along the cylinder -->
      <origin rpy="0 0 0" xyz="0 0 0.145"/>
      <geometry>
        <cylinder length="0.290" radius="0.01"/>
      </geometry>
      <material name="black"/>
    </visual>
    <collision>
      <origin rpy="0 0 0" xyz="0 0 0.145"/>
      <geometry>
        <cylinder length="0.290" radius="0.01"/>
      </geometry>
    </collision>
  </link>

  <joint name="tool_gripper_joint" type="fixed">
    <!-- The 15-degree offset about the z-axis is to account for the fact that the gripper is actually mounted at this offset. -->
    <origin rpy="0 0 0.2617993877991494" xyz="0 0.0 0"/>
    <parent link="ur10_arm_tool0"/>
    <child link="gripper"/>
  </joint>

  <link name="ft_sensor"></link>

  <joint name="tool_ft_sensor_joint" type="fixed">
    <origin rpy="0 0 0" xyz="0 0 0.02"/>
    <parent link="ur10_arm_tool0"/>
    <child link="ft_sensor"/>
  </joint>

</robot>
